Workbook

Sheet Kullanım
A1: TAHAKKUK | Kurumsal Excel
A4: Çalışma alanı | B4: Normal, emekli, engelli ve 6111 teşvik sayfaları ayrı hesaplanır.
A5: Giriş alanları | B5: Çalışan tablolarında ücret, ikramiye ve prim gününü düzenleyin. Formüller otomatik hesaplanır.
A6: Kazanç kaynağı | B6: Emekli ve 6111 sayfalarında B4 hücresindeki elle girilen matrah kullanılır.
A7: Engelli indirimi | B7: Kaynak dosyaya uygun olarak 4857 indirimi başlangıçta toplamdan düşülmez. K14 hücresini 1 yaparak uygulayın.
A8: Ek çalışan grubu | B8: Engelli sayfasındaki ek grup başlangıçta matraha dahil değildir. K15 hücresini 1 yaparak dahil edin.
A9: Hizmet belgeleri | B9: Normal/emekli ek belgeleri ile devam sayfalarının kimlik, tarih ve neden kodu alanlarını düzenleyin.
A10: Oran farkı | B10: Normal ek belgede malullük oranı %20, normal hesaplama sayfasında %21 korunmuştur.
A11: Resmî kontrol | B11: Güncel oranları, prim tavanını ve teşvik uygunluğunu ayrıca kontrol edin. Bu dosya SGK’ya gönderim yapmaz.
A12: Hesaplama | B12: Formüllerin sonuçları Excel veya LibreOffice içinde dosya açılınca yeniden hesaplanır.
A13: Kaynak kayıtlar | B13: Paylaştığınız dosyanın dolu kayıtları aktarılmıştır; kimlik alanları metin olarak korunur.

Sheet Normal Ek Belge
A1: TAHAKKUK | Normal Ek Belge
A4: İşyeri sicil no | B4: 281210101154751003433 | D4: Dönem | E4: 2025-01 | G4: Mahiyeti | H4: İptal
A5: İşveren / ünvan | D5: Belge türü | E5: 01 | G5: Kanun no | H5: 5510
A6: Adres | D6: Telefon / e-posta | G6: Vergi / kimlik no
A8: Sıra | B8: SGK / kimlik no | C8: Adı | D8: Soyadı | E8: İlk soyadı | F8: Gün | G8: Ücret | H8: İkramiye | I8: Giriş tarihi | J8: Çıkış tarihi | K8: Eksik gün | L8: Neden kodu | M8: Çıkış nedeni | N8: Kazanç
A9: 1 | B9: 28265018608 | C9: ÖNDER | D9: KAYA | F9: 29 | G9: 25138.65 | H9: 0 | I9: 2025-01-01 | K9: 0 | L9: 21 | N9: =G9+H9
A10: 2 | F10: 0 | G10: 0 | H10: 0 | K10: 0 | N10: =G10+H10
A11: 3 | F11: 0 | G11: 0 | H11: 0 | K11: 0 | N11: =G11+H11
A12: 4 | F12: 0 | G12: 0 | H12: 0 | K12: 0 | N12: =G12+H12
A13: 5 | F13: 0 | G13: 0 | H13: 0 | K13: 0 | N13: =G13+H13
A14: 6 | F14: 0 | G14: 0 | H14: 0 | K14: 0 | N14: =G14+H14
A15: 7 | F15: 0 | G15: 0 | H15: 0 | K15: 0 | N15: =G15+H15
A17: BU SAYFANIN TOPLAMI | F17: =SUM(F9:F15) | G17: =SUM(G9:G15) | H17: =SUM(H9:H15) | N17: =SUM(N9:N15)
A19: Sigorta kolu | G19: Oran (%) | H19: Prim tutarı
A20: Kısa vadeli sigorta | G20: 2.25 | H20: =('Normal Devam'!N37)*G20/100
A21: Malullük / yaşlılık / ölüm | G21: 20 | H21: =('Normal Devam'!N37)*G21/100
A22: Genel sağlık sigortası | G22: 12.5 | H22: =('Normal Devam'!N37)*G22/100
A23: İşsizlik sigortası | G23: 3 | H23: =('Normal Devam'!N37)*G23/100
A24: Sosyal güvenlik destek primi | G24: 0 | H24: =('Normal Devam'!N37)*G24/100
A26: ÖDENECEK TOPLAM | H26: =SUM(H20:H24)
A28: Mali müşavir adı soyadı | G28: Teslim tarihi
A29: Oda kayıt numarası
A31: İşveren kaşe / imza | G31: Mali müşavir kaşe / imza

Sheet Normal Devam
A1: AYLIK PRİM VE HİZMET | Devam Sayfası
A4: ='Normal Ek Belge'!A4 | B4: ='Normal Ek Belge'!B4 | D4: ='Normal Ek Belge'!D4 | E4: ='Normal Ek Belge'!E4 | G4: ='Normal Ek Belge'!G4 | H4: ='Normal Ek Belge'!H4
A5: ='Normal Ek Belge'!A5 | D5: ='Normal Ek Belge'!D5 | E5: ='Normal Ek Belge'!E5 | G5: ='Normal Ek Belge'!G5 | H5: ='Normal Ek Belge'!H5
A8: Sıra | B8: SGK / kimlik no | C8: Adı | D8: Soyadı | E8: İlk soyadı | F8: Gün | G8: Ücret | H8: İkramiye | I8: Giriş tarihi | J8: Çıkış tarihi | K8: Eksik gün | L8: Neden kodu | M8: Çıkış nedeni | N8: Kazanç
A9: 8 | F9: 0 | G9: 0 | H9: 0 | K9: 0 | N9: =G9+H9
A10: 9 | F10: 0 | G10: 0 | H10: 0 | K10: 0 | N10: =G10+H10
A11: 10 | F11: 0 | G11: 0 | H11: 0 | K11: 0 | N11: =G11+H11
A12: 11 | F12: 0 | G12: 0 | H12: 0 | K12: 0 | N12: =G12+H12
A13: 12 | F13: 0 | G13: 0 | H13: 0 | K13: 0 | N13: =G13+H13
A14: 13 | F14: 0 | G14: 0 | H14: 0 | K14: 0 | N14: =G14+H14
A15: 14 | F15: 0 | G15: 0 | H15: 0 | K15: 0 | N15: =G15+H15
A16: 15 | F16: 0 | G16: 0 | H16: 0 | K16: 0 | N16: =G16+H16
A17: 16 | F17: 0 | G17: 0 | H17: 0 | K17: 0 | N17: =G17+H17
A18: 17 | F18: 0 | G18: 0 | H18: 0 | K18: 0 | N18: =G18+H18
A19: 18 | F19: 0 | G19: 0 | H19: 0 | K19: 0 | N19: =G19+H19
A20: 19 | F20: 0 | G20: 0 | H20: 0 | K20: 0 | N20: =G20+H20
... A33: 32 | F33: 0 | G33: 0 | H33: 0 | K33: 0 | N33: =G33+H33
A35: BU SAYFANIN TOPLAMI | F35: =SUM(F9:F33) | G35: =SUM(G9:G33) | H35: =SUM(H9:H33) | N35: =SUM(N9:N33)
A36: ÖNCEKİ SAYFADAN DEVİR | F36: ='Normal Ek Belge'!F17 | G36: ='Normal Ek Belge'!G17 | H36: ='Normal Ek Belge'!H17 | N36: ='Normal Ek Belge'!N17
A37: BU SAYFA DAHİL TOPLAM | F37: =F35+F36 | G37: =G35+G36 | H37: =H35+H36 | N37: =N35+N36

Sheet Emekli Ek Belge
A1: TAHAKKUK | Emekli Ek Belge
A4: İşyeri sicil no | B4: 481210101154751003433 | D4: Dönem | E4: 2025-01 | G4: Mahiyeti | H4: Ek
A5: İşveren / ünvan | D5: Belge türü | E5: 02 | G5: Kanun no
A6: Adres | D6: Telefon / e-posta | G6: Vergi / kimlik no
A8: Sıra | B8: SGK / kimlik no | C8: Adı | D8: Soyadı | E8: İlk soyadı | F8: Gün | G8: Ücret | H8: İkramiye | I8: Giriş tarihi | J8: Çıkış tarihi | K8: Eksik gün | L8: Neden kodu | M8: Çıkış nedeni | N8: Kazanç
A9: 1 | B9: 28265018608 | C9: ÖNDER | D9: KAYA | F9: 29 | G9: 25138.65 | H9: 0 | I9: 2025-01-01 | K9: 0 | L9: 21 | N9: =G9+H9
A10: 2 | F10: 0 | G10: 0 | H10: 0 | K10: 0 | N10: =G10+H10
A11: 3 | F11: 0 | G11: 0 | H11: 0 | K11: 0 | N11: =G11+H11
A12: 4 | F12: 0 | G12: 0 | H12: 0 | K12: 0 | N12: =G12+H12
A13: 5 | F13: 0 | G13: 0 | H13: 0 | K13: 0 | N13: =G13+H13
A14: 6 | F14: 0 | G14: 0 | H14: 0 | K14: 0 | N14: =G14+H14
A15: 7 | F15: 0 | G15: 0 | H15: 0 | K15: 0 | N15: =G15+H15
A17: BU SAYFANIN TOPLAMI | F17: =SUM(F9:F15) | G17: =SUM(G9:G15) | H17: =SUM(H9:H15) | N17: =SUM(N9:N15)
A19: Sigorta kolu | G19: Oran (%) | H19: Prim tutarı
A20: Kısa vadeli sigorta | G20: 2.25 | H20: =('Emekli Devam'!N37)*G20/100
A21: Malullük / yaşlılık / ölüm | G21: 0 | H21: =('Emekli Devam'!N37)*G21/100
A22: Genel sağlık sigortası | G22: 0 | H22: =('Emekli Devam'!N37)*G22/100
A23: İşsizlik sigortası | G23: 0 | H23: =('Emekli Devam'!N37)*G23/100
A24: Sosyal güvenlik destek primi | G24: 30 | H24: =('Emekli Devam'!N37)*G24/100
A26: ÖDENECEK TOPLAM | H26: =SUM(H20:H24)
A28: Mali müşavir adı soyadı | G28: Teslim tarihi
A29: Oda kayıt numarası
A31: İşveren kaşe / imza | G31: Mali müşavir kaşe / imza

Sheet Emekli Devam
A1: AYLIK PRİM VE HİZMET | Devam Sayfası
A4: ='Emekli Ek Belge'!A4 | B4: ='Emekli Ek Belge'!B4 | D4: ='Emekli Ek Belge'!D4 | E4: ='Emekli Ek Belge'!E4 | G4: ='Emekli Ek Belge'!G4 | H4: ='Emekli Ek Belge'!H4
A5: ='Emekli Ek Belge'!A5 | D5: ='Emekli Ek Belge'!D5 | E5: ='Emekli Ek Belge'!E5 | G5: ='Emekli Ek Belge'!G5 | H5: ='Emekli Ek Belge'!H5
A8: Sıra | B8: SGK / kimlik no | C8: Adı | D8: Soyadı | E8: İlk soyadı | F8: Gün | G8: Ücret | H8: İkramiye | I8: Giriş tarihi | J8: Çıkış tarihi | K8: Eksik gün | L8: Neden kodu | M8: Çıkış nedeni | N8: Kazanç
A9: 8 | F9: 0 | G9: 0 | H9: 0 | K9: 0 | N9: =G9+H9
A10: 9 | F10: 0 | G10: 0 | H10: 0 | K10: 0 | N10: =G10+H10
A11: 10 | F11: 0 | G11: 0 | H11: 0 | K11: 0 | N11: =G11+H11
A12: 11 | F12: 0 | G12: 0 | H12: 0 | K12: 0 | N12: =G12+H12
A13: 12 | F13: 0 | G13: 0 | H13: 0 | K13: 0 | N13: =G13+H13
A14: 13 | F14: 0 | G14: 0 | H14: 0 | K14: 0 | N14: =G14+H14
A15: 14 | F15: 0 | G15: 0 | H15: 0 | K15: 0 | N15: =G15+H15
A16: 15 | F16: 0 | G16: 0 | H16: 0 | K16: 0 | N16: =G16+H16
A17: 16 | F17: 0 | G17: 0 | H17: 0 | K17: 0 | N17: =G17+H17
A18: 17 | F18: 0 | G18: 0 | H18: 0 | K18: 0 | N18: =G18+H18
A19: 18 | F19: 0 | G19: 0 | H19: 0 | K19: 0 | N19: =G19+H19
A20: 19 | F20: 0 | G20: 0 | H20: 0 | K20: 0 | N20: =G20+H20
... A33: 32 | F33: 0 | G33: 0 | H33: 0 | K33: 0 | N33: =G33+H33
A35: BU SAYFANIN TOPLAMI | F35: =SUM(F9:F33) | G35: =SUM(G9:G33) | H35: =SUM(H9:H33) | N35: =SUM(N9:N33)
A36: ÖNCEKİ SAYFADAN DEVİR | F36: ='Emekli Ek Belge'!F17 | G36: ='Emekli Ek Belge'!G17 | H36: ='Emekli Ek Belge'!H17 | N36: ='Emekli Ek Belge'!N17
A37: BU SAYFA DAHİL TOPLAM | F37: =F35+F36 | G37: =G35+G36 | H37: =H35+H36 | N37: =N35+N36

Sheet Normal Çalışan
A1: TAHAKKUK | Normal Çalışan
A4: Prime esas kazanç | B4: =SUM(C9:D58)
A6: Çalışan kazançları
A8: Sıra | B8: Çalışan adı | C8: Ücret | D8: İkramiye | E8: Gün | G8: Kazanç
A9: 1 | C9: 60665 | D9: 0 | E9: 30 | G9: =C9+D9 | J9: Kısa vadeli sigorta | K9: 2.25 | L9: =$B$4*K9/100
A10: 2 | C10: 27777.86 | D10: 0 | E10: 23 | G10: =C10+D10 | J10: Malullük / yaşlılık / ölüm | K10: 21 | L10: =$B$4*K10/100
A11: 3 | C11: 72835 | D11: 2589.69 | E11: 30 | G11: =C11+D11 | J11: Genel sağlık sigortası | K11: 12.5 | L11: =$B$4*K11/100
A12: 4 | C12: 36232 | D12: 644.12 | E12: 30 | G12: =C12+D12 | J12: İşsizlik sigortası | K12: 3 | L12: =$B$4*K12/100
A13: 5 | C13: 40316 | D13: 0 | E13: 30 | G13: =C13+D13 | J13: Sosyal güvenlik destek primi | K13: 0 | L13: =$B$4*K13/100
A14: 6 | C14: 84025 | D14: 17925.34 | E14: 30 | G14: =C14+D14 | J14: 4857 / 6111 indirimi uygulansın (1/0) | K14: 0
A15: 7 | C15: 36232 | D15: 1288.25 | E15: 30 | G15: =C15+D15 | J15: Ek grup dahil edilsin (1/0) | K15: 0
A16: 8 | C16: 51566.66 | D16: 0 | E16: 28 | G16: =C16+D16
A17: 9 | C17: 36232 | D17: 3220.62 | E17: 30 | G17: =C17+D17 | J17: 05510 indirim oranı (%) | K17: 2 | L17: =B4*K17/100
A18: 10 | C18: 36232 | D18: 1932.37 | E18: 30 | G18: =C18+D18 | J18: Teşvik oranı (%) | K18: 0 | L18: =B4*K18/100
A19: 11 | C19: 36232 | D19: 1932.37 | E19: 30 | G19: =C19+D19
A20: 12 | C20: 84025 | D20: 37344.45 | E20: 30 | G20: =C20+D20 | J20: Toplam sigorta primi | L20: =SUM(L9:L11,L13)
A21: 13 | C21: 36232 | D21: 3220.62 | E21: 30 | G21: =C21+D21 | J21: Net sigorta primi | L21: =L20-L17-L18*K14
A22: 14 | C22: 8454.13 | D22: 0 | E22: 7 | G22: =C22+D22 | J22: İşsizlik sigortası | L22: =L12
A23: 15 | C23: 55250 | D23: 0 | E23: 30 | G23: =C23+D23
A24: 16 | C24: 36232 | D24: 644.12 | E24: 30 | G24: =C24+D24 | J24: ÖDENECEK TUTAR | L24: =L21+L22
A25: 17 | C25: 36232 | D25: 1932.37 | E25: 30 | G25: =C25+D25
A26: 18 | C26: 36232 | D26: 644.12 | E26: 30 | G26: =C26+D26 | J26: Toplam prim günü | L26: =SUM(E9:E58)
A27: 19 | C27: 72835 | D27: 15538.14 | E27: 30 | G27: =C27+D27
A28: 20 | C28: 36232 | D28: 0 | E28: 30 | G28: =C28+D28
A29: 21 | C29: 72835 | D29: 10358.76 | E29: 30 | G29: =C29+D29
A30: 22 | C30: 36232 | D30: 1932.37 | E30: 30 | G30: =C30+D30
A31: 23 | C31: 72835 | D31: 28486.57 | E31: 30 | G31: =C31+D31
A32: 24 | C32: 36232 | D32: 3220.62 | E32: 30 | G32: =C32+D32
A33: 25 | C33: 27777.86 | D33: 1932.37 | E33: 23 | G33: =C33+D33
A34: 26 | C34: 36232 | D34: 3220.62 | E34: 30 | G34: =C34+D34
A35: 27 | C35: 36232 | D35: 644.12 | E35: 30 | G35: =C35+D35
A36: 28 | C36: 36232 | D36: 644.12 | E36: 30 | G36: =C36+D36
A37: 29 | C37: 72835 | D37: 2589.69 | E37: 30 | G37: =C37+D37
A38: 30 | C38: 19323.73 | D38: 644.12 | E38: 16 | G38: =C38+D38
... A58: 50 | C58: 0 | D58: 0 | E58: 0 | G58: =C58+D58
B59: TOPLAM | C59: =SUM(C9:C58) | D59: =SUM(D9:D58) | E59: =SUM(E9:E58) | G59: =SUM(G9:G58)

Sheet Emekli Çalışan
A1: TAHAKKUK | Emekli Çalışan
A4: Prime esas kazanç | B4: 2389818.3
A6: Çalışan kazançları
A8: Sıra | B8: Çalışan adı | C8: Ücret | D8: İkramiye | E8: Gün | G8: Kazanç
A9: 1 | C9: 0 | D9: 0 | E9: 0 | G9: =C9+D9 | J9: Kısa vadeli sigorta | K9: 2.25 | L9: =$B$4*K9/100
A10: 2 | C10: 0 | D10: 0 | E10: 0 | G10: =C10+D10 | J10: Malullük / yaşlılık / ölüm | K10: 0 | L10: =$B$4*K10/100
A11: 3 | C11: 0 | D11: 0 | E11: 0 | G11: =C11+D11 | J11: Genel sağlık sigortası | K11: 0 | L11: =$B$4*K11/100
A12: 4 | C12: 0 | D12: 0 | E12: 0 | G12: =C12+D12 | J12: İşsizlik sigortası | K12: 0 | L12: =$B$4*K12/100
A13: 5 | C13: 0 | D13: 0 | E13: 0 | G13: =C13+D13 | J13: Sosyal güvenlik destek primi | K13: 30 | L13: =$B$4*K13/100
A14: 6 | C14: 0 | D14: 0 | E14: 0 | G14: =C14+D14 | J14: 4857 / 6111 indirimi uygulansın (1/0) | K14: 0
A15: 7 | C15: 0 | D15: 0 | E15: 0 | G15: =C15+D15 | J15: Ek grup dahil edilsin (1/0) | K15: 0
A16: 8 | C16: 0 | D16: 0 | E16: 0 | G16: =C16+D16
A17: 9 | C17: 0 | D17: 0 | E17: 0 | G17: =C17+D17 | J17: 05510 indirim oranı (%) | K17: 0 | L17: =B4*K17/100
A18: 10 | C18: 0 | D18: 0 | E18: 0 | G18: =C18+D18 | J18: Teşvik oranı (%) | K18: 0 | L18: =B4*K18/100
A19: 11 | C19: 0 | D19: 0 | E19: 0 | G19: =C19+D19
A20: 12 | C20: 0 | D20: 0 | E20: 0 | G20: =C20+D20 | J20: Toplam sigorta primi | L20: =SUM(L9:L11,L13)
A21: 13 | C21: 0 | D21: 0 | E21: 0 | G21: =C21+D21 | J21: Net sigorta primi | L21: =L20-L17-L18*K14
A22: 14 | C22: 0 | D22: 0 | E22: 0 | G22: =C22+D22 | J22: İşsizlik sigortası | L22: =L12
A23: 15 | C23: 0 | D23: 0 | E23: 0 | G23: =C23+D23
A24: 16 | C24: 0 | D24: 0 | E24: 0 | G24: =C24+D24 | J24: ÖDENECEK TUTAR | L24: =L21+L22
A25: 17 | C25: 0 | D25: 0 | E25: 0 | G25: =C25+D25
A26: 18 | C26: 0 | D26: 0 | E26: 0 | G26: =C26+D26 | J26: Toplam prim günü | L26: =SUM(E9:E58)
A27: 19 | C27: 0 | D27: 0 | E27: 0 | G27: =C27+D27
A28: 20 | C28: 0 | D28: 0 | E28: 0 | G28: =C28+D28
A29: 21 | C29: 0 | D29: 0 | E29: 0 | G29: =C29+D29
A30: 22 | C30: 0 | D30: 0 | E30: 0 | G30: =C30+D30
A31: 23 | C31: 0 | D31: 0 | E31: 0 | G31: =C31+D31
A32: 24 | C32: 0 | D32: 0 | E32: 0 | G32: =C32+D32
A33: 25 | C33: 0 | D33: 0 | E33: 0 | G33: =C33+D33
A34: 26 | C34: 0 | D34: 0 | E34: 0 | G34: =C34+D34
A35: 27 | C35: 0 | D35: 0 | E35: 0 | G35: =C35+D35
A36: 28 | C36: 0 | D36: 0 | E36: 0 | G36: =C36+D36
A37: 29 | C37: 0 | D37: 0 | E37: 0 | G37: =C37+D37
A38: 30 | C38: 0 | D38: 0 | E38: 0 | G38: =C38+D38
... A58: 50 | C58: 0 | D58: 0 | E58: 0 | G58: =C58+D58
B59: TOPLAM | C59: =SUM(C9:C58) | D59: =SUM(D9:D58) | E59: =SUM(E9:E58) | G59: =SUM(G9:G58)

Sheet Engelli Çalışan
A1: TAHAKKUK | Engelli Çalışan
A4: Prime esas kazanç | B4: =SUM(C9:D58)+SUM(C63:D67)*K15
A6: Çalışan kazançları
A8: Sıra | B8: Çalışan adı | C8: Ücret | D8: İkramiye | E8: Gün | G8: Kazanç
A9: 1 | C9: 47238 | D9: 7348.13 | E9: 30 | G9: =C9+D9 | J9: Kısa vadeli sigorta | K9: 2.25 | L9: =$B$4*K9/100
A10: 2 | C10: 54301 | D10: 5792.11 | E10: 30 | G10: =C10+D10 | J10: Malullük / yaşlılık / ölüm | K10: 21 | L10: =$B$4*K10/100
A11: 3 | C11: 54301 | D11: 7964.15 | E11: 30 | G11: =C11+D11 | J11: Genel sağlık sigortası | K11: 12.5 | L11: =$B$4*K11/100
A12: 4 | C12: 47238 | D12: 3988.99 | E12: 30 | G12: =C12+D12 | J12: İşsizlik sigortası | K12: 3 | L12: =$B$4*K12/100
A13: 5 | C13: 47238 | D13: 7558.08 | E13: 30 | G13: =C13+D13 | J13: Sosyal güvenlik destek primi | K13: 0 | L13: =$B$4*K13/100
A14: 6 | C14: 47238 | D14: 7558.08 | E14: 30 | G14: =C14+D14 | J14: 4857 / 6111 indirimi uygulansın (1/0) | K14: 0
A15: 7 | C15: 57141 | D15: 10412.36 | E15: 30 | G15: =C15+D15 | J15: Ek grup dahil edilsin (1/0) | K15: 0
A16: 8 | C16: 47238 | D16: 0 | E16: 30 | G16: =C16+D16
A17: 9 | C17: 47238 | D17: 3988.99 | E17: 30 | G17: =C17+D17 | J17: 05510 indirim oranı (%) | K17: 2 | L17: =B4*K17/100
A18: 10 | C18: 54301 | D18: 4585.42 | E18: 30 | G18: =C18+D18 | J18: Teşvik oranı (%) | K18: 15.75 | L18: =B4*K18/100
A19: 11 | C19: 47238 | D19: 7558.08 | E19: 30 | G19: =C19+D19
A20: 12 | C20: 47238 | D20: 10077.44 | E20: 30 | G20: =C20+D20 | J20: Toplam sigorta primi | L20: =SUM(L9:L11,L13)
A21: 13 | C21: 47238 | D21: 7558.08 | E21: 30 | G21: =C21+D21 | J21: Net sigorta primi | L21: =L20-L17-L18*K14
A22: 14 | C22: 47238 | D22: 6718.29 | E22: 30 | G22: =C22+D22 | J22: İşsizlik sigortası | L22: =L12
A23: 15 | C23: 47238 | D23: 6928.24 | E23: 30 | G23: =C23+D23
A24: 16 | C24: 22825.6 | D24: 8607.81 | E24: 16 | G24: =C24+D24 | J24: ÖDENECEK TUTAR | L24: =L21+L22
A25: 17 | C25: 47238 | D25: 10077.44 | E25: 30 | G25: =C25+D25
A26: 18 | C26: 47238 | D26: 6718.29 | E26: 30 | G26: =C26+D26 | J26: Toplam prim günü | L26: =SUM(E9:E58)+SUM(E63:E67)*K15
A27: 19 | C27: 47238 | D27: 6718.29 | E27: 30 | G27: =C27+D27
A28: 20 | C28: 47238 | D28: 4408.88 | E28: 30 | G28: =C28+D28
A29: 21 | C29: 47238 | D29: 8607.81 | E29: 30 | G29: =C29+D29
A30: 22 | C30: 57141 | D30: 0 | E30: 30 | G30: =C30+D30
A31: 23 | C31: 20469.8 | D31: 6718.29 | E31: 12 | G31: =C31+D31
A32: 24 | C32: 26768.2 | D32: 1679.57 | E32: 15 | G32: =C32+D32
A33: 25 | C33: 47238 | D33: 5038.72 | E33: 30 | G33: =C33+D33
A34: 26 | C34: 45663.4 | D34: 10077.44 | E34: 29 | G34: =C34+D34
A35: 27 | C35: 47238 | D35: 10077.44 | E35: 30 | G35: =C35+D35
A36: 28 | C36: 45663.4 | D36: 1679.57 | E36: 29 | G36: =C36+D36
A37: 29 | C37: 47238 | D37: 4618.83 | E37: 30 | G37: =C37+D37
A38: 30 | C38: 47238 | D38: 5878.51 | E38: 30 | G38: =C38+D38
... A58: 50 | C58: 0 | D58: 0 | E58: 0 | G58: =C58+D58
B59: TOPLAM | C59: =SUM(C9:C58) | D59: =SUM(D9:D58) | E59: =SUM(E9:E58) | G59: =SUM(G9:G58)
B61: EK ÇALIŞAN GRUBU
A62: Sıra | B62: Çalışan adı | C62: Ücret | D62: İkramiye | E62: Gün | G62: Kazanç
A63: 1 | C63: 57141 | D63: 0 | E63: 30 | G63: =C63+D63
A64: 2 | C64: 57141 | D64: 9142.56 | E64: 30 | G64: =C64+D64
...

Sheet 6111 Teşvik
A1: TAHAKKUK | 6111 Teşvik
A4: Prime esas kazanç | B4: 62467.83
A6: Çalışan kazançları
A8: Sıra | B8: Çalışan adı | C8: Ücret | D8: İkramiye | E8: Gün | G8: Kazanç
A9: 1 | C9: 0 | D9: 0 | E9: 0 | G9: =C9+D9 | J9: Kısa vadeli sigorta | K9: 2.25 | L9: =$B$4*K9/100
A10: 2 | C10: 0 | D10: 0 | E10: 0 | G10: =C10+D10 | J10: Malullük / yaşlılık / ölüm | K10: 21 | L10: =$B$4*K10/100
A11: 3 | C11: 0 | D11: 0 | E11: 0 | G11: =C11+D11 | J11: Genel sağlık sigortası | K11: 12.5 | L11: =$B$4*K11/100
A12: 4 | C12: 0 | D12: 0 | E12: 0 | G12: =C12+D12 | J12: İşsizlik sigortası | K12: 3 | L12: =$B$4*K12/100
A13: 5 | C13: 0 | D13: 0 | E13: 0 | G13: =C13+D13 | J13: Sosyal güvenlik destek primi | K13: 0 | L13: =$B$4*K13/100
A14: 6 | C14: 0 | D14: 0 | E14: 0 | G14: =C14+D14 | J14: 4857 / 6111 indirimi uygulansın (1/0) | K14: 1
A15: 7 | C15: 0 | D15: 0 | E15: 0 | G15: =C15+D15 | J15: Ek grup dahil edilsin (1/0) | K15: 0
A16: 8 | C16: 0 | D16: 0 | E16: 0 | G16: =C16+D16
A17: 9 | C17: 0 | D17: 0 | E17: 0 | G17: =C17+D17 | J17: 05510 indirim oranı (%) | K17: 2 | L17: =B4*K17/100
A18: 10 | C18: 0 | D18: 0 | E18: 0 | G18: =C18+D18 | J18: Teşvik oranı (%) | K18: 15.75 | L18: =B4*K18/100
A19: 11 | C19: 0 | D19: 0 | E19: 0 | G19: =C19+D19
A20: 12 | C20: 0 | D20: 0 | E20: 0 | G20: =C20+D20 | J20: Toplam sigorta primi | L20: =SUM(L9:L11,L13)
A21: 13 | C21: 0 | D21: 0 | E21: 0 | G21: =C21+D21 | J21: Net sigorta primi | L21: =L20-L17-L18*K14
A22: 14 | C22: 0 | D22: 0 | E22: 0 | G22: =C22+D22 | J22: İşsizlik sigortası | L22: =L12
A23: 15 | C23: 0 | D23: 0 | E23: 0 | G23: =C23+D23
A24: 16 | C24: 0 | D24: 0 | E24: 0 | G24: =C24+D24 | J24: ÖDENECEK TUTAR | L24: =L21+L22
A25: 17 | C25: 0 | D25: 0 | E25: 0 | G25: =C25+D25
A26: 18 | C26: 0 | D26: 0 | E26: 0 | G26: =C26+D26 | J26: Toplam prim günü | L26: =SUM(E9:E58)
A27: 19 | C27: 0 | D27: 0 | E27: 0 | G27: =C27+D27
A28: 20 | C28: 0 | D28: 0 | E28: 0 | G28: =C28+D28
A29: 21 | C29: 0 | D29: 0 | E29: 0 | G29: =C29+D29
A30: 22 | C30: 0 | D30: 0 | E30: 0 | G30: =C30+D30
A31: 23 | C31: 0 | D31: 0 | E31: 0 | G31: =C31+D31
A32: 24 | C32: 0 | D32: 0 | E32: 0 | G32: =C32+D32
A33: 25 | C33: 0 | D33: 0 | E33: 0 | G33: =C33+D33
A34: 26 | C34: 0 | D34: 0 | E34: 0 | G34: =C34+D34
A35: 27 | C35: 0 | D35: 0 | E35: 0 | G35: =C35+D35
A36: 28 | C36: 0 | D36: 0 | E36: 0 | G36: =C36+D36
A37: 29 | C37: 0 | D37: 0 | E37: 0 | G37: =C37+D37
A38: 30 | C38: 0 | D38: 0 | E38: 0 | G38: =C38+D38
... A58: 50 | C58: 0 | D58: 0 | E58: 0 | G58: =C58+D58
B59: TOPLAM | C59: =SUM(C9:C58) | D59: =SUM(D9:D58) | E59: =SUM(E9:E58) | G59: =SUM(G9:G58)
